<mujoco model="8_link_arm">
  <compiler angle="radian" coordinate="local" inertiafromgeom="true"/>
  <option collision="predefined" density="4000" integrator="RK4" timestep="0.01" viscosity="0.1"/>
  <default>
    <geom conaffinity="1" condim="1" contype="1" material="geom" rgba="0.8 0.6 .4 1"/>
    <joint armature='0.1'  />
  </default>
  <asset>
    <texture builtin="gradient" height="100" rgb1="1 1 1" rgb2="0 0 0" type="skybox" width="100"/>
    <texture builtin="flat" height="1278" mark="cross" markrgb="1 1 1" name="texgeom" random="0.01" rgb1="0.8 0.6 0.4" rgb2="0.8 0.6 0.4" type="cube" width="127"/>
    <material name="geom" texture="texgeom" texuniform="true"/>
  </asset>
  <worldbody>
    <light cutoff="100" diffuse="1 1 1" dir="-0 0 -1.3" directional="true" exponent="1" pos="1.1 0 1.3" specular=".1 .1 .1"/>
    <camera name="topcam" pos="0 0 2.5" zaxis="0 0 1" />
    <body name="body1" pos="0 0 0">
      <geom density="1" size="0.075" type="sphere" rgba="1 1 1 1"/>
      <geom density="1000" fromto="0 0 0.0 0 0 -0.5" size="0.05" type="capsule" rgba="0 1 0.1 1"/>
      <joint axis="0 1 0" name="motor1_rot" type="hinge"/>
      <body name="body2" pos="0 0 -0.5">
        <geom density="1" size="0.075" type="sphere" rgba="1 0 0 1"/>
        <geom density="1000" fromto="0 0 -0 0 0 -0.5" size="0.05" type="capsule" rgba="0 1 0.2 1"/>
        <joint axis="0 1 0" name="motor2_rot" type="hinge"/>
        <body name="body3" pos = "0 0 -0.5">
          <geom density="1" size="0.075" type="sphere" rgba="1 0 0 1"/>
          <geom density="1000" fromto="0 0 0.0 0 0 -0.5" size="0.05" type="capsule" rgba="0 1 0.3 1"/>
          <joint axis="0 1 0" name="motor3_rot" type="hinge"/>
            <body name="body4" pos = "0 0 -0.5">
            <geom density="1" size="0.075" type="sphere" rgba="1 0 0 1"/>
            <geom density="1000" fromto="0 0 0.0 0 0 -0.5" size="0.05" type="capsule" rgba="0 1 0.4 1"/>
            <joint axis="0 1 0" name="motor4_rot" type="hinge"/>
          </body>
        </body>
      </body>
    </body>
  </worldbody>
  <actuator>
    <motor ctrllimited="true" ctrlrange="-1 1" gear="100.0" joint="motor1_rot"/>
    <motor ctrllimited="true" ctrlrange="-1 1" gear="100.0" joint="motor2_rot"/>
    <motor ctrllimited="true" ctrlrange="-1 1" gear="100.0" joint="motor3_rot"/>
    <motor ctrllimited="true" ctrlrange="-1 1" gear="100.0" joint="motor4_rot"/>
  </actuator>
  <sensor>
    <jointpos name="motor1_position_sensor" joint="motor1_rot"/>
    <jointpos name="motor2_position_sensor" joint="motor2_rot"/>
    <jointpos name="motor3_position_sensor" joint="motor3_rot"/>
    <jointpos name="motor4_position_sensor" joint="motor4_rot"/>
    <jointvel name="motor1_velocity_sensor" joint="motor1_rot"/>
    <jointvel name="motor2_velocity_sensor" joint="motor2_rot"/>
    <jointvel name="motor3_velocity_sensor" joint="motor3_rot"/>
    <jointvel name="motor4_velocity_sensor" joint="motor4_rot"/>
  </sensor>
</mujoco>